Workbook

Sheet Dashboard
A1: SAP ACCOUNTS PAYABLE | INVOICE TRACKING DASHBOARD
A2: Demonstration workbook | Fictional data only | Ageing formulas use TODAY()
A4: Total Invoices | C4: Total Invoice Value | E4: Open / Blocked / Parked | G4: Blocked Invoices
A5: =COUNTA('Invoice Tracker'!A2:A101) -> 100 | C5: =SUM('Invoice Tracker'!I2:I101) -> 8551562.1 | E5: =COUNTIF('Invoice Tracker'!J2:J101,"Open")+COUNTIF('Invoice Tracker'!J2:J101,"Blocked")+COUNTIF('Invoice Tracker'!J2:J101,"Parked") -> 64 | G5: =COUNTIF('Invoice Tracker'!J2:J101,"Blocked") -> 21
A8: Invoice Status | E8: Outstanding Ageing
A9: Status | B9: Count | C9: Invoice Value (INR) | E9: Ageing Bucket | F9: Count | G9: Outstanding (INR)
A10: Open | B10: =COUNTIF('Invoice Tracker'!J$2:J$101,A10) -> 35 | C10: =SUMIF('Invoice Tracker'!J$2:J$101,A10,'Invoice Tracker'!I$2:I$101) -> 2873392.5 | E10: Not Due | F10: =COUNTIF('Invoice Tracker'!M$2:M$101,E10) -> 16 | G10: =SUMIFS('Invoice Tracker'!I$2:I$101,'Invoice Tracker'!M$2:M$101,E10,'Invoice Tracker'!J$2:J$101,"<>Paid") -> 1585458.6
A11: Blocked | B11: =COUNTIF('Invoice Tracker'!J$2:J$101,A11) -> 21 | C11: =SUMIF('Invoice Tracker'!J$2:J$101,A11,'Invoice Tracker'!I$2:I$101) -> 1905972.6 | E11: 1-30 Days | F11: =COUNTIF('Invoice Tracker'!M$2:M$101,E11) -> 14 | G11: =SUMIFS('Invoice Tracker'!I$2:I$101,'Invoice Tracker'!M$2:M$101,E11,'Invoice Tracker'!J$2:J$101,"<>Paid") -> 959599.02
A12: Paid | B12: =COUNTIF('Invoice Tracker'!J$2:J$101,A12) -> 36 | C12: =SUMIF('Invoice Tracker'!J$2:J$101,A12,'Invoice Tracker'!I$2:I$101) -> 3113359.9 | E12: 31-60 Days | F12: =COUNTIF('Invoice Tracker'!M$2:M$101,E12) -> 11 | G12: =SUMIFS('Invoice Tracker'!I$2:I$101,'Invoice Tracker'!M$2:M$101,E12,'Invoice Tracker'!J$2:J$101,"<>Paid") -> 500721.12
A13: Parked | B13: =COUNTIF('Invoice Tracker'!J$2:J$101,A13) -> 8 | C13: =SUMIF('Invoice Tracker'!J$2:J$101,A13,'Invoice Tracker'!I$2:I$101) -> 658837.17 | E13: 61-90 Days | F13: =COUNTIF('Invoice Tracker'!M$2:M$101,E13) -> 15 | G13: =SUMIFS('Invoice Tracker'!I$2:I$101,'Invoice Tracker'!M$2:M$101,E13,'Invoice Tracker'!J$2:J$101,"<>Paid") -> 1372431.6
E14: 90+ Days | F14: =COUNTIF('Invoice Tracker'!M$2:M$101,E14) -> 8 | G14: =SUMIFS('Invoice Tracker'!I$2:I$101,'Invoice Tracker'!M$2:M$101,E14,'Invoice Tracker'!J$2:J$101,"<>Paid") -> 1019991.9

Sheet Invoice Tracker
A1: Invoice ID | B1: Vendor ID | C1: Vendor Name | D1: Invoice Type | E1: PO Number | F1: GR Document | G1: Invoice Date | H1: Due Date | I1: Invoice Amount (INR) | J1: Status | K1: Exception / Block Reason | L1: Days Past Due | M1: Ageing Bucket
A2: INV-2026-0001 | B2: V1007 | C2: Granite Packaging | D2: PO-Based | E2: 4581283135 | F2: 4939874144 | G2: 46305 | H2: 46320 | I2: 151575.97 | J2: Open | L2: =IF(OR(J2="Paid",H2>=TODAY()),0,TODAY()-H2) -> 0 | M2: =IF(J2="Paid","Paid",IF(L2=0,"Not Due",IF(L2<=30,"1-30 Days",IF(L2<=60,"31-60 Days",IF(L2<=90,"61-90 Days","90+ Days"))))) -> Not Due
A3: INV-2026-0002 | B3: V1007 | C3: Granite Packaging | D3: PO-Based | E3: 4520023211 | F3: 4998033996 | G3: 46295 | H3: 46325 | I3: 104657.15 | J3: Paid | L3: =IF(OR(J3="Paid",H3>=TODAY()),0,TODAY()-H3) -> 0 | M3: =IF(J3="Paid","Paid",IF(L3=0,"Not Due",IF(L3<=30,"1-30 Days",IF(L3<=60,"31-60 Days",IF(L3<=90,"61-90 Days","90+ Days"))))) -> Paid
A4: INV-2026-0003 | B4: V1006 | C4: Fairview Logistics | D4: Non-PO | G4: 46196 | H4: 46211 | I4: 162608.84 | J4: Open | L4: =IF(OR(J4="Paid",H4>=TODAY()),0,TODAY()-H4) -> 96 | M4: =IF(J4="Paid","Paid",IF(L4=0,"Not Due",IF(L4<=30,"1-30 Days",IF(L4<=60,"31-60 Days",IF(L4<=90,"61-90 Days","90+ Days"))))) -> 90+ Days
A5: INV-2026-0004 | B5: V1005 | C5: Evergreen IT Services | D5: PO-Based | E5: 4571439057 | F5: 4955199941 | G5: 46192 | H5: 46207 | I5: 18545.7 | J5: Paid | L5: =IF(OR(J5="Paid",H5>=TODAY()),0,TODAY()-H5) -> 0 | M5: =IF(J5="Paid","Paid",IF(L5=0,"Not Due",IF(L5<=30,"1-30 Days",IF(L5<=60,"31-60 Days",IF(L5<=90,"61-90 Days","90+ Days"))))) -> Paid
A6: INV-2026-0005 | B6: V1002 | C6: BluePeak Services | D6: PO-Based | E6: 4586406998 | F6: 4965110827 | G6: 46233 | H6: 46248 | I6: 76477.26 | J6: Paid | L6: =IF(OR(J6="Paid",H6>=TODAY()),0,TODAY()-H6) -> 0 | M6: =IF(J6="Paid","Paid",IF(L6=0,"Not Due",IF(L6<=30,"1-30 Days",IF(L6<=60,"31-60 Days",IF(L6<=90,"61-90 Days","90+ Days"))))) -> Paid
A7: INV-2026-0006 | B7: V1008 | C7: Harbor Utilities | D7: Non-PO | G7: 46288 | H7: 46333 | I7: 75615.69 | J7: Open | L7: =IF(OR(J7="Paid",H7>=TODAY()),0,TODAY()-H7) -> 0 | M7: =IF(J7="Paid","Paid",IF(L7=0,"Not Due",IF(L7<=30,"1-30 Days",IF(L7<=60,"31-60 Days",IF(L7<=90,"61-90 Days","90+ Days"))))) -> Not Due
A8: INV-2026-0007 | B8: V1005 | C8: Evergreen IT Services | D8: PO-Based | E8: 4558632342 | F8: 4915478429 | G8: 46287 | H8: 46317 | I8: 13592.22 | J8: Paid | L8: =IF(OR(J8="Paid",H8>=TODAY()),0,TODAY()-H8) -> 0 | M8: =IF(J8="Paid","Paid",IF(L8=0,"Not Due",IF(L8<=30,"1-30 Days",IF(L8<=60,"31-60 Days",IF(L8<=90,"61-90 Days","90+ Days"))))) -> Paid
A9: INV-2026-0008 | B9: V1008 | C9: Harbor Utilities | D9: Non-PO | G9: 46260 | H9: 46305 | I9: 134671.5 | J9: Open | L9: =IF(OR(J9="Paid",H9>=TODAY()),0,TODAY()-H9) -> 2 | M9: =IF(J9="Paid","Paid",IF(L9=0,"Not Due",IF(L9<=30,"1-30 Days",IF(L9<=60,"31-60 Days",IF(L9<=90,"61-90 Days","90+ Days"))))) -> 1-30 Days
A10: INV-2026-0009 | B10: V1008 | C10: Harbor Utilities | D10: PO-Based | E10: 4553096744 | F10: 4940975194 | G10: 46259 | H10: 46274 | I10: 19067.68 | J10: Blocked | K10: Missing GR | L10: =IF(OR(J10="Paid",H10>=TODAY()),0,TODAY()-H10) -> 33 | M10: =IF(J10="Paid","Paid",IF(L10=0,"Not Due",IF(L10<=30,"1-30 Days",IF(L10<=60,"31-60 Days",IF(L10<=90,"61-90 Days","90+ Days"))))) -> 31-60 Days
A11: INV-2026-0010 | B11: V1005 | C11: Evergreen IT Services | D11: PO-Based | E11: 4566995027 | G11: 46187 | H11: 46247 | I11: 30330.28 | J11: Parked | K11: Missing documentation | L11: =IF(OR(J11="Paid",H11>=TODAY()),0,TODAY()-H11) -> 60 | M11: =IF(J11="Paid","Paid",IF(L11=0,"Not Due",IF(L11<=30,"1-30 Days",IF(L11<=60,"31-60 Days",IF(L11<=90,"61-90 Days","90+ Days"))))) -> 31-60 Days
A12: INV-2026-0011 | B12: V1001 | C12: Aster Office Supplies | D12: Non-PO | G12: 46248 | H12: 46263 | I12: 27401.67 | J12: Open | L12: =IF(OR(J12="Paid",H12>=TODAY()),0,TODAY()-H12) -> 44 | M12: =IF(J12="Paid","Paid",IF(L12=0,"Not Due",IF(L12<=30,"1-30 Days",IF(L12<=60,"31-60 Days",IF(L12<=90,"61-90 Days","90+ Days"))))) -> 31-60 Days
A13: INV-2026-0012 | B13: V1004 | C13: Delta Facilities | D13: PO-Based | E13: 4589527644 | F13: 4999162148 | G13: 46203 | H13: 46233 | I13: 115033.53 | J13: Paid | L13: =IF(OR(J13="Paid",H13>=TODAY()),0,TODAY()-H13) -> 0 | M13: =IF(J13="Paid","Paid",IF(L13=0,"Not Due",IF(L13<=30,"1-30 Days",IF(L13<=60,"31-60 Days",IF(L13<=90,"61-90 Days","90+ Days"))))) -> Paid
A14: INV-2026-0013 | B14: V1004 | C14: Delta Facilities | D14: PO-Based | E14: 4585292864 | F14: 4923044035 | G14: 46173 | H14: 46233 | I14: 84383.59 | J14: Paid | L14: =IF(OR(J14="Paid",H14>=TODAY()),0,TODAY()-H14) -> 0 | M14: =IF(J14="Paid","Paid",IF(L14=0,"Not Due",IF(L14<=30,"1-30 Days",IF(L14<=60,"31-60 Days",IF(L14<=90,"61-90 Days","90+ Days"))))) -> Paid
A15: INV-2026-0014 | B15: V1004 | C15: Delta Facilities | D15: Non-PO | G15: 46303 | H15: 46333 | I15: 143199.73 | J15: Paid | L15: =IF(OR(J15="Paid",H15>=TODAY()),0,TODAY()-H15) -> 0 | M15: =IF(J15="Paid","Paid",IF(L15=0,"Not Due",IF(L15<=30,"1-30 Days",IF(L15<=60,"31-60 Days",IF(L15<=90,"61-90 Days","90+ Days"))))) -> Paid
A16: INV-2026-0015 | B16: V1003 | C16: Cedar Industrial | D16: Non-PO | G16: 46224 | H16: 46284 | I16: 125210.39 | J16: Paid | L16: =IF(OR(J16="Paid",H16>=TODAY()),0,TODAY()-H16) -> 0 | M16: =IF(J16="Paid","Paid",IF(L16=0,"Not Due",IF(L16<=30,"1-30 Days",IF(L16<=60,"31-60 Days",IF(L16<=90,"61-90 Days","90+ Days"))))) -> Paid
A17: INV-2026-0016 | B17: V1006 | C17: Fairview Logistics | D17: PO-Based | E17: 4568067144 | F17: 4941181182 | G17: 46205 | H17: 46220 | I17: 20508.28 | J17: Open | L17: =IF(OR(J17="Paid",H17>=TODAY()),0,TODAY()-H17) -> 87 | M17: =IF(J17="Paid","Paid",IF(L17=0,"Not Due",IF(L17<=30,"1-30 Days",IF(L17<=60,"31-60 Days",IF(L17<=90,"61-90 Days","90+ Days"))))) -> 61-90 Days
A18: INV-2026-0017 | B18: V1008 | C18: Harbor Utilities | D18: PO-Based | E18: 4523209775 | G18: 46302 | H18: 46317 | I18: 75597.71 | J18: Open | L18: =IF(OR(J18="Paid",H18>=TODAY()),0,TODAY()-H18) -> 0 | M18: =IF(J18="Paid","Paid",IF(L18=0,"Not Due",IF(L18<=30,"1-30 Days",IF(L18<=60,"31-60 Days",IF(L18<=90,"61-90 Days","90+ Days"))))) -> Not Due
A19: INV-2026-0018 | B19: V1010 | C19: Juniper Components | D19: Non-PO | G19: 46306 | H19: 46336 | I19: 156433.2 | J19: Blocked | K19: Duplicate check | L19: =IF(OR(J19="Paid",H19>=TODAY()),0,TODAY()-H19) -> 0 | M19: =IF(J19="Paid","Paid",IF(L19=0,"Not Due",IF(L19<=30,"1-30 Days",IF(L19<=60,"31-60 Days",IF(L19<=90,"61-90 Days","90+ Days"))))) -> Not Due
A20: INV-2026-0019 | B20: V1006 | C20: Fairview Logistics | D20: PO-Based | E20: 4589096478 | F20: 4959883786 | G20: 46181 | H20: 46196 | I20: 119598.13 | J20: Paid | L20: =IF(OR(J20="Paid",H20>=TODAY()),0,TODAY()-H20) -> 0 | M20: =IF(J20="Paid","Paid",IF(L20=0,"Not Due",IF(L20<=30,"1-30 Days",IF(L20<=60,"31-60 Days",IF(L20<=90,"61-90 Days","90+ Days"))))) -> Paid
A21: INV-2026-0020 | B21: V1007 | C21: Granite Packaging | D21: PO-Based | E21: 4555280153 | F21: 4955094784 | G21: 46164 | H21: 46179 | I21: 130226.68 | J21: Blocked | K21: Missing documentation | L21: =IF(OR(J21="Paid",H21>=TODAY()),0,TODAY()-H21) -> 128 | M21: =IF(J21="Paid","Paid",IF(L21=0,"Not Due",IF(L21<=30,"1-30 Days",IF(L21<=60,"31-60 Days",IF(L21<=90,"61-90 Days","90+ Days"))))) -> 90+ Days
A22: INV-2026-0021 | B22: V1003 | C22: Cedar Industrial | D22: PO-Based | E22: 4558960101 | F22: 4967409903 | G22: 46165 | H22: 46180 | I22: 6294.61 | J22: Paid | L22: =IF(OR(J22="Paid",H22>=TODAY()),0,TODAY()-H22) -> 0 | M22: =IF(J22="Paid","Paid",IF(L22=0,"Not Due",IF(L22<=30,"1-30 Days",IF(L22<=60,"31-60 Days",IF(L22<=90,"61-90 Days","90+ Days"))))) -> Paid
A23: INV-2026-0022 | B23: V1004 | C23: Delta Facilities | D23: PO-Based | E23: 4594193898 | F23: 4926521269 | G23: 46248 | H23: 46263 | I23: 143573.17 | J23: Paid | L23: =IF(OR(J23="Paid",H23>=TODAY()),0,TODAY()-H23) -> 0 | M23: =IF(J23="Paid","Paid",IF(L23=0,"Not Due",IF(L23<=30,"1-30 Days",IF(L23<=60,"31-60 Days",IF(L23<=90,"61-90 Days","90+ Days"))))) -> Paid
A24: INV-2026-0023 | B24: V1005 | C24: Evergreen IT Services | D24: Non-PO | G24: 46239 | H24: 46254 | I24: 25077.05 | J24: Open | L24: =IF(OR(J24="Paid",H24>=TODAY()),0,TODAY()-H24) -> 53 | M24: =IF(J24="Paid","Paid",IF(L24=0,"Not Due",IF(L24<=30,"1-30 Days",IF(L24<=60,"31-60 Days",IF(L24<=90,"61-90 Days","90+ Days"))))) -> 31-60 Days
A25: INV-2026-0024 | B25: V1008 | C25: Harbor Utilities | D25: PO-Based | E25: 4577684323 | F25: 4977729470 | G25: 46166 | H25: 46196 | I25: 108324.32 | J25: Paid | L25: =IF(OR(J25="Paid",H25>=TODAY()),0,TODAY()-H25) -> 0 | M25: =IF(J25="Paid","Paid",IF(L25=0,"Not Due",IF(L25<=30,"1-30 Days",IF(L25<=60,"31-60 Days",IF(L25<=90,"61-90 Days","90+ Days"))))) -> Paid
A26: INV-2026-0025 | B26: V1005 | C26: Evergreen IT Services | D26: PO-Based | E26: 4575571349 | F26: 4927902193 | G26: 46288 | H26: 46348 | I26: 76009.38 | J26: Paid | L26: =IF(OR(J26="Paid",H26>=TODAY()),0,TODAY()-H26) -> 0 | M26: =IF(J26="Paid","Paid",IF(L26=0,"Not Due",IF(L26<=30,"1-30 Days",IF(L26<=60,"31-60 Days",IF(L26<=90,"61-90 Days","90+ Days"))))) -> Paid
A27: INV-2026-0026 | B27: V1005 | C27: Evergreen IT Services | D27: PO-Based | E27: 4574286122 | F27: 4968904834 | G27: 46201 | H27: 46246 | I27: 34246.64 | J27: Open | L27: =IF(OR(J27="Paid",H27>=TODAY()),0,TODAY()-H27) -> 61 | M27: =IF(J27="Paid","Paid",IF(L27=0,"Not Due",IF(L27<=30,"1-30 Days",IF(L27<=60,"31-60 Days",IF(L27<=90,"61-90 Days","90+ Days"))))) -> 61-90 Days
A28: INV-2026-0027 | B28: V1007 | C28: Granite Packaging | D28: PO-Based | E28: 4526192605 | F28: 4922997261 | G28: 46235 | H28: 46280 | I28: 88369.87 | J28: Blocked | K28: Missing approval | L28: =IF(OR(J28="Paid",H28>=TODAY()),0,TODAY()-H28) -> 27 | M28: =IF(J28="Paid","Paid",IF(L28=0,"Not Due",IF(L28<=30,"1-30 Days",IF(L28<=60,"31-60 Days",IF(L28<=90,"61-90 Days","90+ Days"))))) -> 1-30 Days
A29: INV-2026-0028 | B29: V1004 | C29: Delta Facilities | D29: PO-Based | E29: 4554208959 | F29: 4921528726 | G29: 46207 | H29: 46222 | I29: 62761.4 | J29: Blocked | K29: Quantity variance | L29: =IF(OR(J29="Paid",H29>=TODAY()),0,TODAY()-H29) -> 85 | M29: =IF(J29="Paid","Paid",IF(L29=0,"Not Due",IF(L29<=30,"1-30 Days",IF(L29<=60,"31-60 Days",IF(L29<=90,"61-90 Days","90+ Days"))))) -> 61-90 Days
A30: INV-2026-0029 | B30: V1009 | C30: Indigo Consulting | D30: Non-PO | G30: 46275 | H30: 46290 | I30: 113183.34 | J30: Parked | K30: Quantity variance | L30: =IF(OR(J30="Paid",H30>=TODAY()),0,TODAY()-H30) -> 17 | M30: =IF(J30="Paid","Paid",IF(L30=0,"Not Due",IF(L30<=30,"1-30 Days",IF(L30<=60,"31-60 Days",IF(L30<=90,"61-90 Days","90+ Days"))))) -> 1-30 Days
A31: INV-2026-0030 | B31: V1004 | C31: Delta Facilities | D31: PO-Based | E31: 4590485719 | F31: 4983419945 | G31: 46287 | H31: 46332 | I31: 82357.47 | J31: Blocked | K31: Price variance | L31: =IF(OR(J31="Paid",H31>=TODAY()),0,TODAY()-H31) -> 0 | M31: =IF(J31="Paid","Paid",IF(L31=0,"Not Due",IF(L31<=30,"1-30 Days",IF(L31<=60,"31-60 Days",IF(L31<=90,"61-90 Days","90+ Days"))))) -> Not Due
A32: INV-2026-0031 | B32: V1003 | C32: Cedar Industrial | D32: PO-Based | E32: 4596850832 | F32: 4961610506 | G32: 46217 | H32: 46247 | I32: 84622.85 | J32: Paid | L32: =IF(OR(J32="Paid",H32>=TODAY()),0,TODAY()-H32) -> 0 | M32: =IF(J32="Paid","Paid",IF(L32=0,"Not Due",IF(L32<=30,"1-30 Days",IF(L32<=60,"31-60 Days",IF(L32<=90,"61-90 Days","90+ Days"))))) -> Paid
A33: INV-2026-0032 | B33: V1002 | C33: BluePeak Services | D33: PO-Based | E33: 4528065605 | F33: 4985424707 | G33: 46168 | H33: 46183 | I33: 93898.57 | J33: Open | L33: =IF(OR(J33="Paid",H33>=TODAY()),0,TODAY()-H33) -> 124 | M33: =IF(J33="Paid","Paid",IF(L33=0,"Not Due",IF(L33<=30,"1-30 Days",IF(L33<=60,"31-60 Days",IF(L33<=90,"61-90 Days","90+ Days"))))) -> 90+ Days
A34: INV-2026-0033 | B34: V1009 | C34: Indigo Consulting | D34: PO-Based | E34: 4532900947 | F34: 4977125890 | G34: 46307 | H34: 46337 | I34: 124622.45 | J34: Parked | K34: Missing documentation | L34: =IF(OR(J34="Paid",H34>=TODAY()),0,TODAY()-H34) -> 0 | M34: =IF(J34="Paid","Paid",IF(L34=0,"Not Due",IF(L34<=30,"1-30 Days",IF(L34<=60,"31-60 Days",IF(L34<=90,"61-90 Days","90+ Days"))))) -> Not Due
A35: INV-2026-0034 | B35: V1001 | C35: Aster Office Supplies | D35: PO-Based | E35: 4510253011 | G35: 46230 | H35: 46260 | I35: 40605.76 | J35: Open | L35: =IF(OR(J35="Paid",H35>=TODAY()),0,TODAY()-H35) -> 47 | M35: =IF(J35="Paid","Paid",IF(L35=0,"Not Due",IF(L35<=30,"1-30 Days",IF(L35<=60,"31-60 Days",IF(L35<=90,"61-90 Days","90+ Days"))))) -> 31-60 Days
A36: INV-2026-0035 | B36: V1005 | C36: Evergreen IT Services | D36: PO-Based | E36: 4580406943 | F36: 4955568454 | G36: 46177 | H36: 46207 | I36: 144620.75 | J36: Paid | L36: =IF(OR(J36="Paid",H36>=TODAY()),0,TODAY()-H36) -> 0 | M36: =IF(J36="Paid","Paid",IF(L36=0,"Not Due",IF(L36<=30,"1-30 Days",IF(L36<=60,"31-60 Days",IF(L36<=90,"61-90 Days","90+ Days"))))) -> Paid
A37: INV-2026-0036 | B37: V1004 | C37: Delta Facilities | D37: Non-PO | G37: 46248 | H37: 46263 | I37: 38955.32 | J37: Open | L37: =IF(OR(J37="Paid",H37>=TODAY()),0,TODAY()-H37) -> 44 | M37: =IF(J37="Paid","Paid",IF(L37=0,"Not Due",IF(L37<=30,"1-30 Days",IF(L37<=60,"31-60 Days",IF(L37<=90,"61-90 Days","90+ Days"))))) -> 31-60 Days
A38: INV-2026-0037 | B38: V1005 | C38: Evergreen IT Services | D38: PO-Based | E38: 4582082801 | F38: 4965413609 | G38: 46249 | H38: 46264 | I38: 122227.05 | J38: Paid | L38: =IF(OR(J38="Paid",H38>=TODAY()),0,TODAY()-H38) -> 0 | M38: =IF(J38="Paid","Paid",IF(L38=0,"Not Due",IF(L38<=30,"1-30 Days",IF(L38<=60,"31-60 Days",IF(L38<=90,"61-90 Days","90+ Days"))))) -> Paid
A39: INV-2026-0038 | B39: V1001 | C39: Aster Office Supplies | D39: PO-Based | E39: 4558620273 | G39: 46166 | H39: 46211 | I39: 110686.4 | J39: Open | L39: =IF(OR(J39="Paid",H39>=TODAY()),0,TODAY()-H39) -> 96 | M39: =IF(J39="Paid","Paid",IF(L39=0,"Not Due",IF(L39<=30,"1-30 Days",IF(L39<=60,"31-60 Days",IF(L39<=90,"61-90 Days","90+ Days"))))) -> 90+ Days
A40: INV-2026-0039 | B40: V1010 | C40: Juniper Components | D40: PO-Based | E40: 4559129009 | F40: 4961776587 | G40: 46286 | H40: 46331 | I40: 124706.36 | J40: Open | L40: =IF(OR(J40="Paid",H40>=TODAY()),0,TODAY()-H40) -> 0 | M40: =IF(J40="Paid","Paid",IF(L40=0,"Not Due",IF(L40<=30,"1-30 Days",IF(L40<=60,"31-60 Days",IF(L40<=90,"61-90 Days","90+ Days"))))) -> Not Due
...

Sheet Read Me
A1: PROJECT GUIDE — SAP AP INVOICE TRACKING
A3: Purpose | B3: Demonstrate invoice monitoring, ageing analysis, status reporting, and exception tracking for an Accounts Payable process.
A4: Data | B4: 100 fictional invoices and fictional vendor names. No real company or supplier data is used.
A5: How to use | B5: Open Invoice Tracker and filter by Status, Invoice Type, Vendor, or Ageing Bucket.
A6: Ageing logic | B6: Days Past Due and Ageing Bucket use TODAY(). Paid invoices are labelled Paid and excluded from outstanding ageing value.
A7: Dashboard | B7: KPI cards, status summaries, ageing summaries, and a chart use Excel formulas. If formulas show blank values, open in desktop Excel and recalculate.
A8: Important | B8: This is a portfolio simulation, not a live SAP extract. Actual business rules and SAP configuration can differ by organization.
